Workbook
Name _Toc139665495: 'Test Scenarios'!#REF!
Name _Toc185826750: 'Test Scenarios'!#REF!
Name _Toc277595909: 'Test Scenarios'!#REF!
Name _Toc277595910: 'Test Scenarios'!#REF!
Name _Toc277595911: 'Test Scenarios'!#REF!
Name _Toc277595914: 'Test Scenarios'!#REF!
Name _Toc277595917: 'Test Scenarios'!#REF!
Name _Toc277595918: 'Test Scenarios'!#REF!
Name _Toc277595920: 'Test Scenarios'!#REF!
Name _Toc277595922: 'Test Scenarios'!#REF!
Name _Toc277595923: 'Test Scenarios'!#REF!
Name _Toc277595925: 'Test Scenarios'!#REF!
Name HistoryVersions: '[1]Document Control'!$D$15:$D$16
Name Personel_Roles: '[1]Control and Data'!$A$2:$A$15

Sheet Document Control
A8: Document Control
A11: 1. Change History
A13: Version | B13: Date | C13: Summary of Changes | D13: Authors
A14: v0.1 | B14: 45786 | C14: Draft Version | D14: Chandra Sekhar
A20: 2. Distribution
A22: Name | B22: Area | C22: Date | D22: Version
A31: 3. References
A33: # | B33: Document Title | D33: Version
A34: 1 | B34: https://vihaan-ai.atlassian.net/wiki/spaces/DT/pages/323094249/Performance+Test+Strategy+-+AISmart | D34: 0.1

Sheet Project Overview
A7: Project Overview
A9: Complete this sheet to identify basic data used to populate other sheets and headers.
A11: Client / Project Name | B11: AI Smart
A12: Scope matrix filename | B12: Work Load Model
A13: Delivery/Non-Delivery | B13: Delivery
A16: Test Name
A17: Average Load Test
A18: Peak Load test
A19: Stress Load Test
A20: Incremental Load Test
A21: Endurance Test

Sheet Facts & Consideration
A6: Facts & Assumptions
A7: The following facts and assumption were used in creation of the Work Load Model.
A9: # | B9: Date | C9: Description | D9: Comments
A10: 1 | B10: 45786 | C10: Derived the Volumetric data from Performance test strategy document. | D10: Project Input
A11: 2 | B11: 45792 | C11: ThinkTime is 95 | D11: Assumption
A12: 3 | B12: 45792 | C12: Response Time is 5 | D12: Assumption
A13: 5 | B13: 45792 | C13: Current production volume | D13: Project Input
A14: 6 | B14: 45795 | C14: Movementsheet engineering has two transactions so divided the total load by 2 | D14: Assumption
A15: 7 | B15: 45795 | C15: Engineering cntrl board has two transactions so divided the total load by 2 | D15: Assumption
A16: 8 | B16: 45796 | C16: Fuel Compliance has four transactions so divided the total load by 4 | D16: Assumption

Sheet Business Scenario
A1: # | B1: Scenario Description | C1: Scenarios Flows | D1: Transaction Name | E1: Page Views | F1: % Distribution [ Analytics ]
A2: 1 | B2: E2E | C2: Modules | D2: Control Board | E2: 75 | F2: =E2/$E$17 -> 0.20833333
D3: Dispatch | E3: 50 | F3: =E3/$E$17 -> 0.13888889
D4: IROPS | E4: 10 | F4: =E4/$E$17 -> 0.027777778
D5: Movement Sheet | E5: 2.5 | F5: =E5/$E$17 -> 0.0069444444
D6: Movement Sheet | E6: 2.5 | F6: =E6/$E$17 -> 0.0069444444
D7: User Management | E7: 5 | F7: =E7/$E$17 -> 0.013888889 | H7: Load | I7: TPS | J7: RT | K7: TT | L7: Concurrent Users
D8: Engineering Control Board(Duty Manager) | E8: 37.5 | F8: =E8/$E$17 -> 0.10416667 | H8: Peak Hour Metrics | I8: =E17/3600 -> 0.1 | J8: 5 | K8: 95 | L8: =_xlfn.FLOOR.MATH(I8*(J8+K8)) -> 10
D9: Engineering Control Board(Technician) | E9: 37.5 | F9: =E9/$E$17 -> 0.10416667
D10: WorkList | E10: 50 | F10: =E10/$E$17 -> 0.13888889
D11: Fuel Compliance (Engineering) | E11: 12.5 | F11: =E11/$E$17 -> 0.034722222
D12: Fuel Compliance (Cargo) | E12: 12.5 | F12: =E12/$E$17 -> 0.034722222
D13: Fuel Compliance (CLC) | E13: 12.5 | F13: =E13/$E$17 -> 0.034722222
D14: Fuel Compliance (Dispatch) | E14: 12.5 | F14: =E14/$E$17 -> 0.034722222
D15: Reports | E15: 15 | F15: =E15/$E$17 -> 0.041666667
D16: PTS Dashboard | E16: 25 | F16: =E16/$E$17 -> 0.069444444
D17: Total Pageviews | E17: =SUM(E2:E16) -> 360 | F17: =SUM(F2:F16) -> 1
D20: Year over Year Growth | E20: 1 | F20: =E17*1 -> 360

Sheet PageLevelDistribution
B2: # | C2: Page Level Distribution | D2: Column1 | E2: Column2 | F2: Column3 | G2: Column4
C3: Transaction Name | D3: Page Views | E3: % Distribution | F3: % Actual | G3: % Delta | J3: SC01-Control Board (Admin 14) | O3: SC02-Dispatch (Admin 14) | T3: SC03-IROPS (Admin 14)
B4: 1 | C4: Control Board | D4: ='Business Scenario'!E2 -> 75 | E4: ='Business Scenario'!F2 -> 0.20833333 | F4: =M20 -> 0.208 | G4: =F4-E4 -> -0.00033333333 | J4: Page | K4: Count | L4: %age | M4: Total % | O4: Page | P4: Count | Q4: %age | R4: Total % | T4: Page | U4: Count | V4: %age | W4: Total %
B5: 2 | C5: Dispatch | D5: ='Business Scenario'!E3 -> 50 | E5: ='Business Scenario'!F3 -> 0.13888889 | F5: =R29 -> 0.139 | G5: =F5-E5 -> 0.00011111111 | J5: Launch URL | K5: 1 | L5: 0.02 | M5: =K5*L5 -> 0.02 | O5: Launch URL | P5: 1 | Q5: 0.009 | R5: =P5*Q5 -> 0.009 | T5: Launch URL | U5: 1 | V5: 0.003 | W5: =U5*V5 -> 0.003
B6: 3 | C6: IROPS | D6: ='Business Scenario'!E4 -> 10 | E6: ='Business Scenario'!F4 -> 0.027777778 | F6: =W20 -> 0.028 | G6: =F6-E6 -> 0.00022222222 | J6: Login | K6: 1 | L6: 0.02 | M6: =K6*L6 -> 0.02 | O6: Login | P6: 1 | Q6: 0.009 | R6: =P6*Q6 -> 0.009 | T6: Login | U6: 1 | V6: 0.0029 | W6: =U6*V6 -> 0.0029
B7: 4 | C7: Movement Sheet | D7: ='Business Scenario'!E5 -> 2.5 | E7: ='Business Scenario'!F5 -> 0.0069444444 | F7: =M51 -> 0.007 | G7: =F7-E7 -> 5.5555556e-05 | J7: Homepage | K7: 1 | L7: 0.02 | M7: =K7*L7 -> 0.02 | O7: Homepage | P7: 1 | Q7: 0.009 | R7: =P7*Q7 -> 0.009 | T7: Homepage | U7: 1 | V7: 0.0017 | W7: =U7*V7 -> 0.0017
B8: 5 | C8: Movement Sheet | D8: ='Business Scenario'!E6 -> 2.5 | E8: ='Business Scenario'!F6 -> 0.0069444444 | F8: =R52 -> 0.007 | G8: =F8-E8 -> 5.5555556e-05 | J8: Change the location | K8: 1 | L8: 0.02 | M8: =K8*L8 -> 0.02 | O8: Click on Dispatch Module | P8: 1 | Q8: 0.009 | R8: =P8*Q8 -> 0.009 | T8: Click on IRROPS module | U8: 1 | V8: 0.0017 | W8: =U8*V8 -> 0.0017
B9: 6 | C9: User Management | D9: ='Business Scenario'!E7 -> 5 | E9: ='Business Scenario'!F7 -> 0.013888889 | F9: =W43 -> 0.014 | G9: =F9-E9 -> 0.00011111111 | J9: Select Previous Date and Apply Filter | K9: 1 | L9: 0.02 | M9: =K9*L9 -> 0.02 | O9: Change the location | P9: 1 | Q9: 0.008 | R9: =P9*Q9 -> 0.008 | T9: Select Custom Date and Apply | U9: 1 | V9: 0.0017 | W9: =U9*V9 -> 0.0017
B10: 7 | C10: Engineering Control Board(Duty Manager) | D10: ='Business Scenario'!E8 -> 37.5 | E10: ='Business Scenario'!F8 -> 0.10416667 | F10: =M69 -> 0.104 | G10: =F10-E10 -> -0.00016666667 | J10: Select current date and select movement type as Arriving/ALL and Apply Filter | K10: 1 | L10: 0.018 | M10: =K10*L10 -> 0.018 | O10: Change the timezone | P10: 1 | Q10: 0.005 | R10: =P10*Q10 -> 0.005 | T10: Search theTime Zone and Apply | U10: 1 | V10: 0.0017 | W10: =U10*V10 -> 0.0017
B11: 8 | C11: Engineering Control Board(Technician) | D11: ='Business Scenario'!E9 -> 37.5 | E11: ='Business Scenario'!F9 -> 0.10416667 | F11: =R68 -> 0.104 | G11: =F11-E11 -> -0.00016666667 | J11: Timezone change. | K11: 1 | L11: 0.01 | M11: =K11*L11 -> 0.01 | O11: Select Date filter as Today and apply | P11: 1 | Q11: 0.005 | R11: =P11*Q11 -> 0.005 | T11: Search Flight No./Tail No. and Apply | U11: 1 | V11: 0.0017 | W11: =U11*V11 -> 0.0017
B12: 9 | C12: WorkList | D12: ='Business Scenario'!E10 -> 50 | E12: ='Business Scenario'!F10 -> 0.13888889 | F12: =W69 -> 0.139 | G12: =F12-E12 -> 0.00011111111 | J12: Filter dialog box - SortBy | K12: 1 | L12: 0.01 | M12: =K12*L12 -> 0.01 | O12: Select Date filter as Tomorrow and apply | P12: 1 | Q12: 0.005 | R12: =P12*Q12 -> 0.005 | T12: Click on Deactivate tab | U12: 1 | V12: 0.0017 | W12: =U12*V12 -> 0.0017
B13: 10 | C13: Fuel Compliance (Engineering) | D13: ='Business Scenario'!E11 -> 12.5 | E13: ='Business Scenario'!F11 -> 0.034722222 | F13: =M86 -> 0.035 | G13: =F13-E13 -> 0.00027777778 | J13: Apply Past window for all time frames. | K13: 1 | L13: 0.01 | M13: =K13*L13 -> 0.01 | O13: Select Date filter as Yesterday and apply | P13: 1 | Q13: 0.005 | R13: =P13*Q13 -> 0.005 | T13: Activate the lotNo. | U13: 1 | V13: 0.0017 | W13: =U13*V13 -> 0.0017
B14: 11 | C14: Fuel Compliance (Cargo) | D14: ='Business Scenario'!E12 -> 12.5 | E14: ='Business Scenario'!F12 -> 0.034722222 | F14: =R86 -> 0.035 | G14: =F14-E14 -> 0.00027777778 | J14: Click on Arrival Station | K14: 1 | L14: 0.01 | M14: =K14*L14 -> 0.01 | O14: Select Date filter as Custom Range and apply | P14: 1 | Q14: 0.005 | R14: =P14*Q14 -> 0.005 | T14: Click on Manual Intervention | U14: 1 | V14: 0.0017 | W14: =U14*V14 -> 0.0017
B15: 12 | C15: Fuel Compliance (CLC) | D15: ='Business Scenario'!E13 -> 12.5 | E15: ='Business Scenario'!F13 -> 0.034722222 | F15: =W86 -> 0.035 | G15: =F15-E15 -> 0.00027777778 | J15: Click on Departure Station | K15: 1 | L15: 0.01 | M15: =K15*L15 -> 0.01 | O15: Search Flight and apply. | P15: 1 | Q15: 0.005 | R15: =P15*Q15 -> 0.005 | T15: Click Lot no., add email & save | U15: 1 | V15: 0.0017 | W15: =U15*V15 -> 0.0017
B16: 13 | C16: Fuel Compliance (Dispatch) | D16: ='Business Scenario'!E14 -> 12.5 | E16: ='Business Scenario'!F14 -> 0.034722222 | F16: =M104 -> 0.035 | G16: =F16-E16 -> 0.00027777778 | J16: Click on Pax | K16: 1 | L16: 0.01 | M16: =K16*L16 -> 0.01 | O16: Click on Download ADC/FIC, select date and click Generate Report | P16: 1 | Q16: 0.005 | R16: =P16*Q16 -> 0.005 | T16: Publish the lot No. | U16: 1 | V16: 0.0017 | W16: =U16*V16 -> 0.0017
B17: 14 | C17: Reports | D17: ='Business Scenario'!E15 -> 15 | E17: ='Business Scenario'!F15 -> 0.041666667 | F17: =R108 -> 0.042 | G17: =F17-E17 -> 0.00033333333 | J17: Click on Captain/First Officer | K17: 1 | L17: 0.01 | M17: =K17*L17 -> 0.01 | O17: Click on Active MELs and Download | P17: 1 | Q17: 0.005 | R17: =P17*Q17 -> 0.005 | T17: Click on Manual Intervention and change the bucket to Basket. | U17: 1 | V17: 0.0017 | W17: =U17*V17 -> 0.0017
B18: 15 | C18: PTS Dashboard | D18: ='Business Scenario'!E16 -> 25 | E18: ='Business Scenario'!F16 -> 0.069444444 | F18: =W102 -> 0.069 | G18: =F18-E18 -> -0.00044444444 | J18: Click on CFG | K18: 1 | L18: 0.01 | M18: =K18*L18 -> 0.01 | O18: Click on CrewDetails | P18: 1 | Q18: 0.005 | R18: =P18*Q18 -> 0.005 | T18: Click on Generate Report & Download PDF/Excel. | U18: 1 | V18: 0.0017 | W18: =U18*V18 -> 0.0017
C19: Total Pageviews | D19: =SUM(D4:D18) -> 360 | E19: =SUM(E4:E18) -> 1 | J19: Click on Profile and Logout | K19: 1 | L19: 0.01 | M19: =K19*L19 -> 0.01 | O19: Click on More Details. | P19: 1 | Q19: 0.005 | R19: =P19*Q19 -> 0.005 | T19: Click on Profile and Logout | U19: 1 | V19: 0.0017 | W19: =U19*V19 -> 0.0017
K20: =SUM(K5:K19) -> 15 | M20: =SUM(M5:M19) -> 0.208 | O20: Click on Allocate Dispatcher | P20: 1 | Q20: 0.005 | R20: =P20*Q20 -> 0.005 | U20: =SUM(U5:U19) -> 15 | W20: =SUM(W5:W19) -> 0.028
O21: Click on Allocated | P21: 1 | Q21: 0.005 | R21: =P21*Q21 -> 0.005
O22: Click on Unallocated | P22: 1 | Q22: 0.005 | R22: =P22*Q22 -> 0.005
O23: Select aircraft type | P23: 1 | Q23: 0.005 | R23: =P23*Q23 -> 0.005
O24: Select Start time | P24: 1 | Q24: 0.005 | R24: =P24*Q24 -> 0.005
O25: Select End Time. | P25: 1 | Q25: 0.005 | R25: =P25*Q25 -> 0.005
O26: Assign Dispatcher. | P26: 1 | Q26: 0.005 | R26: =P26*Q26 -> 0.005
O27: Update Dispatcher (Click on Allocated). | P27: 1 | Q27: 0.005 | R27: =P27*Q27 -> 0.005
O28: Click on Profile and Logout | P28: 1 | Q28: 0.005 | R28: =P28*Q28 -> 0.005
P29: =SUM(P5:P28) -> 24 | R29: =SUM(R5:R28) -> 0.139
J33: SC04-Movement Sheet (Admin) | O33: SC05-Movement Sheet (Engineering 11 Role:DepHead SubRole:AME ENG) | T33: SC06-User Management (Admin SuperUser 14)
J34: Page | K34: Count | L34: %age | M34: Total % | O34: Page | P34: Count | Q34: %age | R34: Total % | T34: Page | U34: Count | V34: %age | W34: Total %
J35: Launch URL | K35: 1 | L35: 0.0005 | M35: =K35*L35 -> 0.0005 | O35: Launch URL | P35: 1 | Q35: 0.0005 | R35: =P35*Q35 -> 0.0005 | T35: Launch URL | U35: 1 | V35: 0.002 | W35: =U35*V35 -> 0.002
J36: Login | K36: 1 | L36: 0.0005 | M36: =K36*L36 -> 0.0005 | O36: Login | P36: 1 | Q36: 0.0005 | R36: =P36*Q36 -> 0.0005 | T36: Login | U36: 1 | V36: 0.002 | W36: =U36*V36 -> 0.002
J37: Homepage | K37: 1 | L37: 0.0005 | M37: =K37*L37 -> 0.0005 | O37: Homepage | P37: 1 | Q37: 0.0004 | R37: =P37*Q37 -> 0.0004 | T37: Homepage | U37: 1 | V37: 0.002 | W37: =U37*V37 -> 0.002
J38: Click on the Movement sheet Module | K38: 1 | L38: 0.0005 | M38: =K38*L38 -> 0.0005 | O38: Click on the Movement sheet Module | P38: 1 | Q38: 0.0004 | R38: =P38*Q38 -> 0.0004 | T38: Click on User Management Module | U38: 1 | V38: 0.002 | W38: =U38*V38 -> 0.002
J39: Change the Timezone | K39: 1 | L39: 0.0005 | M39: =K39*L39 -> 0.0005 | O39: Change TimeZone | P39: 1 | Q39: 0.0004 | R39: =P39*Q39 -> 0.0004 | T39: Click on Add User, Provide details and Click on Save. | U39: 1 | V39: 0.002 | W39: =U39*V39 -> 0.002
J40: Change the location | K40: 1 | L40: 0.0005 | M40: =K40*L40 -> 0.0005 | O40: Change the location | P40: 1 | Q40: 0.0004 | R40: =P40*Q40 -> 0.0004 | T40: Click on Edit, update the deatils and click on Save. | U40: 1 | V40: 0.002 | W40: =U40*V40 -> 0.002
J41: Search for flight/Tail No. and apply filter. | K41: 1 | L41: 0.0004 | M41: =K41*L41 -> 0.0004 | O41: Search for flight/Tail No. and apply filter. | P41: 1 | Q41: 0.0004 | R41: =P41*Q41 -> 0.0004 | T41: Click on Delete. | U41: 1 | V41: 0.001 | W41: =U41*V41 -> 0.001
J42: Select Custom date and apply filter | K42: 1 | L42: 0.0004 | M42: =K42*L42 -> 0.0004 | O42: Select Custom date and apply filter | P42: 1 | Q42: 0.0004 | R42: =P42*Q42 -> 0.0004 | T42: Click on Profile and Logout | U42: 1 | V42: 0.001 | W42: =U42*V42 -> 0.001
J43: Select Custom date and Time Frame D and apply filter | K43: 1 | L43: 0.0004 | M43: =K43*L43 -> 0.0004 | O43: Select Custom date and Time Frame D and apply filter | P43: 1 | Q43: 0.0004 | R43: =P43*Q43 -> 0.0004 | U43: =SUM(U35:U42) -> 8 | W43: =SUM(W35:W42) -> 0.014
J44: Select Custom date and Time Frame D+1 and apply filter | K44: 1 | L44: 0.0004 | M44: =K44*L44 -> 0.0004 | O44: Select Custom date and Time Frame D+1 and apply filter | P44: 1 | Q44: 0.0004 | R44: =P44*Q44 -> 0.0004
...

Sheet Work Load Mix-PeakLoad
A2: Peak Load Transaction Mix - Year 2025
A3: SNo | B3: Scenario Name | C3: Perf (Y/N) | D3: User Type [Existing/Guest] | E3: Load Distribution | F3: Pages / Hour | G3: Pages/ Sec(TPS) | H3: Pages/ Iteration | I3: Loops/hr | J3: Concurrent Users | K3: Average RT / Page in sec | L3: Average Total RT/ loop in sec | M3: Thinktime / loop in sec | N3: Thinktime /Call in sec | O3: Total PageTime /loop in sec
A4: 1 | B4: Control Board | C4: Y | D4: Existing | E4: =PageLevelDistribution!F4 -> 0.208 | F4: =(E4*$F$19) -> 74.88 | G4: =F4/3600 -> 0.0208 | H4: =PageLevelDistribution!K20 -> 15 | I4: =F4/H4 -> 4.992 | J4: =(E4*$J$19) -> 2.08 | K4: 5 | L4: =K4*H4 -> 75 | M4: =(3600/(I4/J4)-L4) -> 1425 | N4: =M4/H4 -> 95 | O4: =M4+L4 -> 1500
A5: 2 | B5: Dispatch | C5: Y | D5: Existing | E5: =PageLevelDistribution!F5 -> 0.139 | F5: =(E5*$F$19) -> 50.04 | G5: =F5/3600 -> 0.0139 | H5: =PageLevelDistribution!P29 -> 24 | I5: =F5/H5 -> 2.085 | J5: =(E5*$J$19) -> 1.39 | K5: 5 | L5: =K5*H5 -> 120 | M5: =(3600/(I5/J5)-L5) -> 2280 | N5: =M5/H5 -> 95 | O5: =M5+L5 -> 2400
A6: 3 | B6: IROPS | C6: Y | D6: Existing | E6: =PageLevelDistribution!F6 -> 0.028 | F6: =(E6*$F$19) -> 10.08 | G6: =F6/3600 -> 0.0028 | H6: =PageLevelDistribution!U20 -> 15 | I6: =F6/H6 -> 0.672 | J6: =(E6*$J$19) -> 0.28 | K6: 5 | L6: =K6*H6 -> 75 | M6: =(3600/(I6/J6)-L6) -> 1425 | N6: =M6/H6 -> 95 | O6: =M6+L6 -> 1500
A7: 4 | B7: Movement Sheet | C7: Y | D7: Existing | E7: =PageLevelDistribution!F7 -> 0.007 | F7: =(E7*$F$19) -> 2.52 | G7: =F7/3600 -> 0.0007 | H7: =PageLevelDistribution!K51 -> 16 | I7: =F7/H7 -> 0.1575 | J7: =(E7*$J$19) -> 0.07 | K7: 5 | L7: =K7*H7 -> 80 | M7: =(3600/(I7/J7)-L7) -> 1520 | N7: =M7/H7 -> 95 | O7: =M7+L7 -> 1600
A8: 5 | B8: Movement Sheet | C8: Y | D8: Existing | E8: =PageLevelDistribution!F8 -> 0.007 | F8: =(E8*$F$19) -> 2.52 | G8: =F8/3600 -> 0.0007 | H8: =PageLevelDistribution!P52 -> 17 | I8: =F8/H8 -> 0.14823529 | J8: =(E8*$J$19) -> 0.07 | K8: 5 | L8: =K8*H8 -> 85 | M8: =(3600/(I8/J8)-L8) -> 1615 | N8: =M8/H8 -> 95 | O8: =M8+L8 -> 1700
A9: 6 | B9: User Management | C9: Y | D9: Existing | E9: =PageLevelDistribution!F9 -> 0.014 | F9: =(E9*$F$19) -> 5.04 | G9: =F9/3600 -> 0.0014 | H9: =PageLevelDistribution!U43 -> 8 | I9: =F9/H9 -> 0.63 | J9: =(E9*$J$19) -> 0.14 | K9: 5 | L9: =K9*H9 -> 40 | M9: =(3600/(I9/J9)-L9) -> 760 | N9: =M9/H9 -> 95 | O9: =M9+L9 -> 800
A10: 7 | B10: Engineering Control Board(Duty Manager) | C10: Y | D10: Existing | E10: =PageLevelDistribution!F10 -> 0.104 | F10: =(E10*$F$19) -> 37.44 | G10: =F10/3600 -> 0.0104 | H10: =PageLevelDistribution!K69 -> 11 | I10: =F10/H10 -> 3.4036364 | J10: =(E10*$J$19) -> 1.04 | K10: 5 | L10: =K10*H10 -> 55 | M10: =(3600/(I10/J10)-L10) -> 1045 | N10: =M10/H10 -> 95 | O10: =M10+L10 -> 1100
A11: 8 | B11: Engineering Control Board(Technician) | C11: Y | D11: Existing | E11: =PageLevelDistribution!F11 -> 0.104 | F11: =(E11*$F$19) -> 37.44 | G11: =F11/3600 -> 0.0104 | H11: =PageLevelDistribution!P68 -> 10 | I11: =F11/H11 -> 3.744 | J11: =(E11*$J$19) -> 1.04 | K11: 5 | L11: =K11*H11 -> 50 | M11: =(3600/(I11/J11)-L11) -> 950 | N11: =M11/H11 -> 95 | O11: =M11+L11 -> 1000
A12: 9 | B12: WorkList | C12: Y | D12: Existing | E12: =PageLevelDistribution!F12 -> 0.139 | F12: =(E12*$F$19) -> 50.04 | G12: =F12/3600 -> 0.0139 | H12: =PageLevelDistribution!U69 -> 11 | I12: =F12/H12 -> 4.5490909 | J12: =(E12*$J$19) -> 1.39 | K12: 5 | L12: =K12*H12 -> 55 | M12: =(3600/(I12/J12)-L12) -> 1045 | N12: =M12/H12 -> 95 | O12: =M12+L12 -> 1100
A13: 10 | B13: Fuel Compliance (Engineering) | C13: Y | D13: Existing | E13: =PageLevelDistribution!F13 -> 0.035 | F13: =(E13*$F$19) -> 12.6 | G13: =F13/3600 -> 0.0035 | H13: =PageLevelDistribution!K86 -> 11 | I13: =F13/H13 -> 1.1454545 | J13: =(E13*$J$19) -> 0.35 | K13: 5 | L13: =K13*H13 -> 55 | M13: =(3600/(I13/J13)-L13) -> 1045 | N13: =M13/H13 -> 95 | O13: =M13+L13 -> 1100
A14: 11 | B14: Fuel Compliance (Cargo) | C14: Y | D14: Existing | E14: =PageLevelDistribution!F14 -> 0.035 | F14: =(E14*$F$19) -> 12.6 | G14: =F14/3600 -> 0.0035 | H14: =PageLevelDistribution!P86 -> 11 | I14: =F14/H14 -> 1.1454545 | J14: =(E14*$J$19) -> 0.35 | K14: 5 | L14: =K14*H14 -> 55 | M14: =(3600/(I14/J14)-L14) -> 1045 | N14: =M14/H14 -> 95 | O14: =M14+L14 -> 1100
A15: 12 | B15: Fuel Compliance (CLC) | C15: Y | D15: Existing | E15: =PageLevelDistribution!F15 -> 0.035 | F15: =(E15*$F$19) -> 12.6 | G15: =F15/3600 -> 0.0035 | H15: =PageLevelDistribution!U86 -> 11 | I15: =F15/H15 -> 1.1454545 | J15: =(E15*$J$19) -> 0.35 | K15: 5 | L15: =K15*H15 -> 55 | M15: =(3600/(I15/J15)-L15) -> 1045 | N15: =M15/H15 -> 95 | O15: =M15+L15 -> 1100
A16: 13 | B16: Fuel Compliance (Dispatch) | C16: Y | D16: Existing | E16: =PageLevelDistribution!F16 -> 0.035 | F16: =(E16*$F$19) -> 12.6 | G16: =F16/3600 -> 0.0035 | H16: =PageLevelDistribution!K104 -> 12 | I16: =F16/H16 -> 1.05 | J16: =(E16*$J$19) -> 0.35 | K16: 5 | L16: =K16*H16 -> 60 | M16: =(3600/(I16/J16)-L16) -> 1140 | N16: =M16/H16 -> 95 | O16: =M16+L16 -> 1200
A17: 14 | B17: Reports | C17: Y | D17: Existing | E17: =PageLevelDistribution!F17 -> 0.042 | F17: =(E17*$F$19) -> 15.12 | G17: =F17/3600 -> 0.0042 | H17: =PageLevelDistribution!P108 -> 16 | I17: =F17/H17 -> 0.945 | J17: =(E17*$J$19) -> 0.42 | K17: 5 | L17: =K17*H17 -> 80 | M17: =(3600/(I17/J17)-L17) -> 1520 | N17: =M17/H17 -> 95 | O17: =M17+L17 -> 1600
A18: 15 | B18: PTS Dashboard | C18: Y | D18: Existing | E18: =PageLevelDistribution!F18 -> 0.069 | F18: =(E18*$F$19) -> 24.84 | G18: =F18/3600 -> 0.0069 | H18: =PageLevelDistribution!U102 -> 10 | I18: =F18/H18 -> 2.484 | J18: =(E18*$J$19) -> 0.69 | K18: 5 | L18: =K18*H18 -> 50 | M18: =(3600/(I18/J18)-L18) -> 950 | N18: =M18/H18 -> 95 | O18: =M18+L18 -> 1000
E19: 1 | F19: ='Business Scenario'!F20 -> 360 | G19: =SUM(G4:G18) -> 0.1001 | H19: =SUM(H4:H18) -> 198 | I19: =SUM(I4:I18) -> 28.296826 | J19: ='Business Scenario'!L8 -> 10

Sheet Test Scenarios
A2: Performance Test Scenarios
A3: Below are the type of tests which are in-scope for application
A4: Sno | B4: Test | C4: Condition | D4: Test Description | E4: Objective | F4: Metrics Analyzed | G4: Load used
A5: 1 | B5: Average Load | C5: Performance | D5: Average Peak Test is to monitor the system’s behavior under a normal production mix load. | E5: Under normal production conditions with normal load, this test shows application behavior for day today transactions. | F5: Response Times CPU Memory Logging Disk | G5: Average Load
A6: 2 | B6: Peak Load | C6: Performance | D6: Peak Test is to monitor the system’s behavior under a peak hour production mix load. | E6: Under normal production conditions, this test shows what the maximum system utilization will be | F6: Response Times CPU Memory Logging Disk Connections Threads | G6: Peak Load
A7: 4 | B7: Endurance Test | C7: Performance | D7: This test is designed to simulate a production-like scenario of constant 50% peak average volumes against application for a normal day. The test is run for 8-12 hour at an average load | E7: This simulation will reveal any server problems related to long periods of volume. Overall, this test shows the server’s ability to maintain its vital metrics over extended durations. Also helps to identify the systen memory leakage if any. | F7: Response Times CPU Memory Logging Disk Connections Threads GC pattern | G7: Average Load
A8: 5 | B8: Stress Test | C8: Performance | D8: This test is designed to find out the breaking point of the application. | E8: This test helps in understanding the stressing point of the application and further this test will revels whether breaking point will be due to code issue or it will be resources utilization issue. | F8: Response Times CPU Memory Logging Disk Connections Threads | G8: Incremental Load to the max, till bottleneck is reached in the system
